<robot xmlns:ns0="http://gazebosim.org/schema" name="alpha">
  <link name="base_link" />
  
  
  
  
  <joint name="base_link_pbase" type="fixed">
    <parent link="base_link" />
    <child link="pbase" />
    <origin rpy="0 0 0" xyz="-0.21365 0 0.1015" />
  </joint>
  <link name="pbase">
    
    <visual>
      <origin rpy="0 0 0" xyz="0.2 0 -0.1015" />
      <geometry>
        <mesh filename="file://../../../platform_description/meshes/car_base_upper.dae" scale="1.0 1.0 1.0" />
      </geometry>
    </visual>
    
    <inertial>
      <mass value="63.5" />
      <origin rpy="0 0 0" xyz="-0.210908  0.045366 -0.000383" />
      <inertia ixx="4.432194" ixy=" -0.384732" ixz="-0.009286" iyy="6.854979" iyz=" -0.002950" izz="9.189479" />
    </inertial>
    
    <collision>
      <origin rpy="0 0 0" xyz="0 0 0.37" />
      <geometry>
        <box size="1.14 0.601 0.74" />
      </geometry>
    </collision>
  </link>
  
  <link name="wheel1">
    <visual>
      <geometry>
        <mesh filename="file://../../../platform_description/meshes/wheel_mesh.dae" scale="1.0 1.0 1.0" />
      </geometry>
    </visual>
    <collision>
      <origin rpy="-1.5708 0 0" xyz="0 0 0" />
      <geometry>
        <cylinder length="0.105" radius="0.1015" />
      </geometry>
    </collision>
    <inertial>
      <mass value="8.0" />
      <inertia ixx="0.027954499999999997" ixy="0.0" ixz="0.0" iyy="0.027954499999999997" iyz="0.0" izz="0.041209" />
    </inertial>
  </link>
  
  <joint name="joint_wheel1" type="continuous">
    <parent link="pbase" />
    <child link="wheel1" />
    <axis xyz="0 1 0" />
    <limit command_effort="1000.0" current="10" effort="1000.0" gear_velocity="100.0" velocity="100.0" />
    <origin rpy="0 0 0" xyz="0.371 0.2509 0" />
  </joint>
  <ros2_control name="DuaDrive_joint_wheel1" type="system">
    <hardware>
      <plugin>mock_components/GenericSystem</plugin>
      <param name="calculate_dynamics">true</param>
    </hardware>
    <joint name="joint_wheel1">
      <state_interface name="position" />
      <state_interface name="velocity" />
      <state_interface name="effort" />
      <state_interface name="temperature_system" />
      <state_interface name="temperature_coil_A" />
      <state_interface name="temperature_coil_B" />
      <state_interface name="temperature_coil_C" />
      <state_interface name="bus_voltage" />
      <command_interface name="position" />
      <command_interface name="velocity" />
      <command_interface name="effort" />
      <command_interface name="p_gain" />
      <command_interface name="i_gain" />
      <command_interface name="d_gain" />
    </joint>
    <gpio name="joint_wheel1">
      <command_interface name="freeze_mode" />
    </gpio>
  </ros2_control>
  
  <gazebo reference="wheel1">
    <collision>
      <surface>
        <friction>
          <ode>
            <mu>1.0</mu>
            
            <mu2>0.0</mu2>
            
            <fdir1 ns0:expressed_in="base_link">1 -1 0</fdir1>
            
          </ode>
        </friction>
      </surface>
    </collision>
  </gazebo>
  
  <link name="wheel2">
    <visual>
      <geometry>
        <mesh filename="file://../../../platform_description/meshes/wheel_mesh.dae" scale="1.0 1.0 1.0" />
      </geometry>
    </visual>
    <collision>
      <origin rpy="-1.5708 0 0" xyz="0 0 0" />
      <geometry>
        <cylinder length="0.105" radius="0.1015" />
      </geometry>
    </collision>
    <inertial>
      <mass value="8.0" />
      <inertia ixx="0.027954499999999997" ixy="0.0" ixz="0.0" iyy="0.027954499999999997" iyz="0.0" izz="0.041209" />
    </inertial>
  </link>
  
  <joint name="joint_wheel2" type="continuous">
    <parent link="pbase" />
    <child link="wheel2" />
    <axis xyz="0 1 0" />
    <limit command_effort="1000.0" current="10" effort="1000.0" gear_velocity="100.0" velocity="100.0" />
    <origin rpy="0 0 0" xyz="0.371 -0.2509 0" />
  </joint>
  <ros2_control name="DuaDrive_joint_wheel2" type="system">
    <hardware>
      <plugin>mock_components/GenericSystem</plugin>
      <param name="calculate_dynamics">true</param>
    </hardware>
    <joint name="joint_wheel2">
      <state_interface name="position" />
      <state_interface name="velocity" />
      <state_interface name="effort" />
      <state_interface name="temperature_system" />
      <state_interface name="temperature_coil_A" />
      <state_interface name="temperature_coil_B" />
      <state_interface name="temperature_coil_C" />
      <state_interface name="bus_voltage" />
      <command_interface name="position" />
      <command_interface name="velocity" />
      <command_interface name="effort" />
      <command_interface name="p_gain" />
      <command_interface name="i_gain" />
      <command_interface name="d_gain" />
    </joint>
    <gpio name="joint_wheel2">
      <command_interface name="freeze_mode" />
    </gpio>
  </ros2_control>
  
  <gazebo reference="wheel2">
    <collision>
      <surface>
        <friction>
          <ode>
            <mu>1.0</mu>
            
            <mu2>0.0</mu2>
            
            <fdir1 ns0:expressed_in="base_link">1 1 0</fdir1>
            
          </ode>
        </friction>
      </surface>
    </collision>
  </gazebo>
  
  <link name="wheel3">
    <visual>
      <geometry>
        <mesh filename="file://../../../platform_description/meshes/wheel_mesh.dae" scale="1.0 1.0 1.0" />
      </geometry>
    </visual>
    <collision>
      <origin rpy="-1.5708 0 0" xyz="0 0 0" />
      <geometry>
        <cylinder length="0.105" radius="0.1015" />
      </geometry>
    </collision>
    <inertial>
      <mass value="8.0" />
      <inertia ixx="0.027954499999999997" ixy="0.0" ixz="0.0" iyy="0.027954499999999997" iyz="0.0" izz="0.041209" />
    </inertial>
  </link>
  
  <joint name="joint_wheel3" type="continuous">
    <parent link="pbase" />
    <child link="wheel3" />
    <axis xyz="0 1 0" />
    <limit command_effort="1000.0" current="10" effort="1000.0" gear_velocity="100.0" velocity="100.0" />
    <origin rpy="0 0 0" xyz="-0.40215 -0.2509 0" />
  </joint>
  <ros2_control name="DuaDrive_joint_wheel3" type="system">
    <hardware>
      <plugin>mock_components/GenericSystem</plugin>
      <param name="calculate_dynamics">true</param>
    </hardware>
    <joint name="joint_wheel3">
      <state_interface name="position" />
      <state_interface name="velocity" />
      <state_interface name="effort" />
      <state_interface name="temperature_system" />
      <state_interface name="temperature_coil_A" />
      <state_interface name="temperature_coil_B" />
      <state_interface name="temperature_coil_C" />
      <state_interface name="bus_voltage" />
      <command_interface name="position" />
      <command_interface name="velocity" />
      <command_interface name="effort" />
      <command_interface name="p_gain" />
      <command_interface name="i_gain" />
      <command_interface name="d_gain" />
    </joint>
    <gpio name="joint_wheel3">
      <command_interface name="freeze_mode" />
    </gpio>
  </ros2_control>
  
  <gazebo reference="wheel3">
    <collision>
      <surface>
        <friction>
          <ode>
            <mu>1.0</mu>
            
            <mu2>0.0</mu2>
            
            <fdir1 ns0:expressed_in="base_link">1 -1 0</fdir1>
            
          </ode>
        </friction>
      </surface>
    </collision>
  </gazebo>
  
  <link name="wheel4">
    <visual>
      <geometry>
        <mesh filename="file://../../../platform_description/meshes/wheel_mesh.dae" scale="1.0 1.0 1.0" />
      </geometry>
    </visual>
    <collision>
      <origin rpy="-1.5708 0 0" xyz="0 0 0" />
      <geometry>
        <cylinder length="0.105" radius="0.1015" />
      </geometry>
    </collision>
    <inertial>
      <mass value="8.0" />
      <inertia ixx="0.027954499999999997" ixy="0.0" ixz="0.0" iyy="0.027954499999999997" iyz="0.0" izz="0.041209" />
    </inertial>
  </link>
  
  <joint name="joint_wheel4" type="continuous">
    <parent link="pbase" />
    <child link="wheel4" />
    <axis xyz="0 1 0" />
    <limit command_effort="1000.0" current="10" effort="1000.0" gear_velocity="100.0" velocity="100.0" />
    <origin rpy="0 0 0" xyz="-0.40215 0.2509 0" />
  </joint>
  <ros2_control name="DuaDrive_joint_wheel4" type="system">
    <hardware>
      <plugin>mock_components/GenericSystem</plugin>
      <param name="calculate_dynamics">true</param>
    </hardware>
    <joint name="joint_wheel4">
      <state_interface name="position" />
      <state_interface name="velocity" />
      <state_interface name="effort" />
      <state_interface name="temperature_system" />
      <state_interface name="temperature_coil_A" />
      <state_interface name="temperature_coil_B" />
      <state_interface name="temperature_coil_C" />
      <state_interface name="bus_voltage" />
      <command_interface name="position" />
      <command_interface name="velocity" />
      <command_interface name="effort" />
      <command_interface name="p_gain" />
      <command_interface name="i_gain" />
      <command_interface name="d_gain" />
    </joint>
    <gpio name="joint_wheel4">
      <command_interface name="freeze_mode" />
    </gpio>
  </ros2_control>
  
  <gazebo reference="wheel4">
    <collision>
      <surface>
        <friction>
          <ode>
            <mu>1.0</mu>
            
            <mu2>0.0</mu2>
            
            <fdir1 ns0:expressed_in="base_link">1 1 0</fdir1>
            
          </ode>
        </friction>
      </surface>
    </collision>
  </gazebo>
  
  <link name="lidar">
    <visual>
      <origin rpy="0 0 0" xyz="0 0 0" />
      <geometry>
        <mesh filename="file://../../../platform_description/meshes/rplidar_c1_with_appendix_mesh.dae" scale="1.0 1.0 1.0" />
      </geometry>
    </visual>
  </link>
  
  <joint name="pbase_lidar" type="fixed">
    <parent link="pbase" />
    <child link="lidar" />
    <origin rpy="0 0 3.141592653589793" xyz="0.47511 0 0.33290" />
  </joint>
  
  <gazebo reference="lidar">
    <sensor name="rplidar" type="gpu_lidar">
      <gz_frame_id>lidar</gz_frame_id>
      <update_rate>10</update_rate>
      <visualize>true</visualize>
      <lidar>
        <scan>
          <horizontal>
            <samples>720</samples>
            <resolution>1</resolution>
            <min_angle>-3.14</min_angle>
            <max_angle>3.14</max_angle>
          </horizontal>
          <vertical>
            <samples>1</samples>
            <min_angle>0</min_angle>
            <max_angle>0</max_angle>
          </vertical>
        </scan>
        <range>
          <min>0.1</min>
          <max>20.0</max>
          <resolution>0.01</resolution>
        </range>
        <noise type="gaussian">
          <mean>0.0</mean>
          <stddev>0.01</stddev>
        </noise>
      </lidar>
    </sensor>
  </gazebo>
  
  <link name="imu" />
  
  <joint name="pbase_imu" type="fixed">
    <parent link="pbase" />
    <child link="imu" />
    <origin rpy="0 0 0" xyz="0.0 0.0 0.0" />
  </joint>
  
  <gazebo reference="imu">
    <gravity>true</gravity>
    <sensor name="imu_sensor" type="imu">
      <always_on>true</always_on>
      <update_rate>100</update_rate>
      <imu>
        <angular_velocity>
          <x>
            <noise type="gaussian">
              <mean>0.0</mean>
              <stddev>0.001</stddev>
            </noise>
          </x>
          <y>
            <noise type="gaussian">
              <mean>0.0</mean>
              <stddev>0.001</stddev>
            </noise>
          </y>
          <z>
            <noise type="gaussian">
              <mean>0.0</mean>
              <stddev>0.001</stddev>
            </noise>
          </z>
        </angular_velocity>
        <linear_acceleration>
          <x>
            <noise type="gaussian">
              <mean>0.0</mean>
              <stddev>0.0001</stddev>
            </noise>
          </x>
          <y>
            <noise type="gaussian">
              <mean>0.0</mean>
              <stddev>0.0001</stddev>
            </noise>
          </y>
          <z>
            <noise type="gaussian">
              <mean>0.0</mean>
              <stddev>0.0001</stddev>
            </noise>
          </z>
        </linear_acceleration>
      </imu>
    </sensor>
  </gazebo>
  <link name="platform_flange">
    <visual>
      <origin rpy="0 0 0" xyz="0 0 0" />
      <geometry>
        <box size="0.001 0.001 0.001" />
      </geometry>
    </visual>
    <inertial>
      <origin rpy="0 0 0" xyz="0.0 0.0 0.0" />
      <mass value="0.001" />
      <inertia ixx="0.0000001" ixy="0.0" ixz="0.0" iyy="0.0000001" iyz="0.0" izz="0.0000001" />
    </inertial>
    <collision>
      <origin rpy="0 0 0" xyz="0 0 0" />
      <geometry>
        <box size="0.001 0.001 0.001" />
      </geometry>
    </collision>
  </link>
  <joint name="platform_to_platform_flange" type="fixed">
    <parent link="pbase" />
    <child link="platform_flange" />
    <limit effort="2000" lower="0" upper="0" velocity="0" />
    <origin rpy="0 0 0" xyz="0.21365 0 0.77640" />
  </joint>
  
  <link name="hip_roll">
    <visual>
      <geometry>
        <mesh filename="file://../../../alpha_description/meshes/hip_roll_mesh.dae" scale="1.0 1.0 1.0" />
      </geometry>
    </visual>
    <inertial>
      <mass value="0.01" />
      <origin rpy="0 0 0" xyz="8.222640999999999e-06 -0.000310936808 -0.036738569268" />
      <inertia ixx="0.0027672584741849997" ixy="3.9341411499999997e-07" ixz="-1.49570272e-07" iyy="0.0028951601054409996" iyz="2.532409214e-05" izz="0.003138952392041" />
    </inertial>
    <collision>
      <origin rpy="0 0 0" xyz="0 0 0.090595" />
      <geometry>
        <cylinder length="0.0308" radius="0.069" />
      </geometry>
    </collision>
  </link>
  <joint name="hip_roll" type="revolute">
    <parent link="platform_flange" />
    <child link="hip_roll" />
    <axis xyz="0 0 1" />
    <limit command_effort="100.0" current="10" effort="100.0" gear_velocity="1.5" lower="-3.22886" upper="3.22886" velocity="1.5" />
    
    <origin rpy="0.0 0.0 0.0" xyz="0.0 0.0 0.0" />
  </joint>
  <link name="hip_pitch">
    <visual>
      <geometry>
        <mesh filename="file://../../../alpha_description/meshes/hip_pitch_mesh.dae" scale="1.0 1.0 1.0" />
      </geometry>
    </visual>
    <inertial>
      <mass value="1.894" />
      <origin rpy="0 0 0" xyz="8.222640999999999e-06 -0.000310936808 -0.036738569268" />
      <inertia ixx="0.0027672584741849997" ixy="3.9341411499999997e-07" ixz="-1.49570272e-07" iyy="0.0028951601054409996" iyz="2.532409214e-05" izz="0.003138952392041" />
    </inertial>
    <collision>
      <origin rpy="1.5707963267948966 0 0" xyz="0 0 0" />
      <geometry>
        <cylinder length="0.342" radius="0.0895" />
      </geometry>
    </collision>
  </link>
  <joint name="hip_pitch" type="revolute">
    <parent link="hip_roll" />
    <child link="hip_pitch" />
    <axis xyz="0 1 0" />
    <limit command_effort="100.0" current="10" effort="100.0" gear_velocity="1.5" lower="-1.48353" upper="1.48353" velocity="1.5" />
    
    <origin rpy="0 0 0" xyz="0.0 0.0 0.108" />
  </joint>
  <link name="hip_flange">
    <visual>
      <origin rpy="0 0 0" xyz="0 0 0" />
      <geometry>
        <box size="0.001 0.001 0.001" />
      </geometry>
    </visual>
    <inertial>
      <origin rpy="0 0 0" xyz="0.0 0.0 0.0" />
      <mass value="0.001" />
      <inertia ixx="0.0000001" ixy="0.0" ixz="0.0" iyy="0.0000001" iyz="0.0" izz="0.0000001" />
    </inertial>
    <collision>
      <origin rpy="0 0 0" xyz="0 0 0" />
      <geometry>
        <box size="0.001 0.001 0.001" />
      </geometry>
    </collision>
  </link>
  <joint name="hip_flange_fix_joint" type="fixed">
    <parent link="hip_pitch" />
    <child link="hip_flange" />
    <limit effort="2000" lower="0" upper="0" velocity="0" />
    <origin rpy="0 0 0" xyz="0 0 0.090" />
  </joint>
  <ros2_control name="Hip" type="system">
    <hardware>
      <plugin>hip_driver/HipMockHardwareInterface</plugin>
      <param name="initial_positions">[0.0001, 0.0001]</param>
    </hardware>
    <joint name="hip_roll">
      <param name="address">1</param>
      <state_interface name="position" />
      <state_interface name="velocity" />
      <state_interface name="acceleration" />
      <state_interface name="effort" />
      <state_interface name="position_commanded" />
      <state_interface name="velocity_commanded" />
      <state_interface name="acceleration_commanded" />
      <state_interface name="effort_commanded" />
      <state_interface name="p_gain_commanded" />
      <state_interface name="i_gain_commanded" />
      <state_interface name="d_gain_commanded" />
      <command_interface name="position" />
      <command_interface name="velocity" />
      <command_interface name="acceleration" />
      <command_interface name="effort" />
      <command_interface name="p_gain" />
      <command_interface name="i_gain" />
      <command_interface name="d_gain" />
    </joint>
    <joint name="hip_pitch">
      <param name="address">2</param>
      <state_interface name="position" />
      <state_interface name="velocity" />
      <state_interface name="acceleration" />
      <state_interface name="effort" />
      <state_interface name="position_commanded" />
      <state_interface name="velocity_commanded" />
      <state_interface name="acceleration_commanded" />
      <state_interface name="effort_commanded" />
      <state_interface name="p_gain_commanded" />
      <state_interface name="i_gain_commanded" />
      <state_interface name="d_gain_commanded" />
      <command_interface name="position" />
      <command_interface name="velocity" />
      <command_interface name="acceleration" />
      <command_interface name="effort" />
      <command_interface name="p_gain" />
      <command_interface name="i_gain" />
      <command_interface name="d_gain" />
    </joint>
    <gpio name="Hip">
      <command_interface name="freeze_mode" />
    </gpio>
  </ros2_control>
  
  <material name="aluminum">
    <color rgba="0.5 0.5 0.5 1" />
  </material>
  <material name="plastic">
    <color rgba="0.1 0.1 0.1 1" />
  </material>
  <joint name="joint_tbase" type="fixed">
    <parent link="hip_flange" />
    <child link="tbase" />
    <limit effort="2000" lower="0" upper="0" velocity="0" />
    <origin rpy="0 0 0" xyz="0 0 0" />
  </joint>
  <link name="tbase">
    <visual>
      <geometry>
        <mesh filename="file://../../../alpha_description/meshes/torso_mesh.dae" scale="1.0 1.0 1.0" />
      </geometry>
    </visual>
    <inertial>
      <mass value="9.5" />
      
      <origin rpy="0 0 0" xyz="-0.0060 -0.000067 0.33383" />
      <inertia ixx="0.423443" ixy="-0.000029" ixz="-0.002288" iyy="0.403430" iyz=" 0.000136" izz="0.080819" />
    </inertial>
    <collision>
      <origin rpy="0 0 0" xyz="0.0 0.0 0.252" />
      <geometry>
        <box size="0.238 0.277 0.504" />
      </geometry>
    </collision>
    <collision>
      <origin rpy="0 0 0" xyz="0.0 0.0 0.592" />
      <geometry>
        <box size="0.32 0.442 0.176" />
      </geometry>
    </collision>
  </link>
  <link name="thead">
    <visual>
      <geometry>
        <mesh filename="file://../../../alpha_description/meshes/head_mesh.dae" scale="1.0 1.0 1.0" />
      </geometry>
    </visual>
    <inertial>
      <mass value="0.666507" />
      <origin rpy="0 0 0" xyz=" 0.018960 -0.000011 0.077322" />
      <inertia ixx="0.004555" ixy=" 0.000000" ixz=" 0.000162" iyy="0.002225" iyz="0.000000" izz=" 0.004885" />
    </inertial>
    <collision>
      <origin rpy="0 0 0" xyz="0.014545 0.001293 0.0785" />
      <geometry>
        <box size="0.148 0.28 0.157" />
      </geometry>
    </collision>
  </link>
  <joint name="thead_fix_joint" type="fixed">
    <parent link="tbase" />
    <child link="thead" />
    <limit effort="2000" lower="0" upper="0" velocity="0" />
    <origin rpy="0.0 0.0 0.0" xyz="0.0 0.0 0.610" />
  </joint>
  
  <joint name="camera_joint" type="fixed">
    <origin rpy="0 0.85521 0" xyz="0.0945 0 0.008" />
    <parent link="thead" />
    <child link="camera_bottom_screw_frame" />
  </joint>
  <link name="camera_bottom_screw_frame" />
  <joint name="camera_link_joint" type="fixed">
    <origin rpy="0 0 0" xyz="0.010600000000000002 0.0175 0.0125" />
    <parent link="camera_bottom_screw_frame" />
    <child link="camera_link" />
  </joint>
  <link name="camera_link">
    <visual>
      
      <origin rpy="1.5707963267948966 0 1.5707963267948966" xyz="0.0043 -0.0175 0" />
      <geometry>
        <mesh filename="file://../../../realsense2_description/meshes/d435.dae" />
      </geometry>
    </visual>
    <collision>
      <origin rpy="0 0 0" xyz="0 -0.0175 0" />
      <geometry>
        <box size="0.02505 0.09 0.025" />
      </geometry>
    </collision>
    <inertial>
      
      <mass value="0.072" />
      <origin xyz="0 0 0" />
      <inertia ixx="0.003881243" ixy="0.0" ixz="0.0" iyy="0.000498940" iyz="0.0" izz="0.003879257" />
    </inertial>
  </link>
  
  <joint name="camera_depth_joint" type="fixed">
    <origin rpy="0 0 0" xyz="0 0 0" />
    <parent link="camera_link" />
    <child link="camera_depth_frame" />
  </joint>
  <link name="camera_depth_frame" />
  <joint name="camera_depth_optical_joint" type="fixed">
    <origin rpy="-1.5707963267948966 0 -1.5707963267948966" xyz="0 0 0" />
    <parent link="camera_depth_frame" />
    <child link="camera_depth_optical_frame" />
  </joint>
  <link name="camera_depth_optical_frame" />
  
  <joint name="camera_infra1_joint" type="fixed">
    <origin rpy="0 0 0" xyz="0 0.0 0" />
    <parent link="camera_link" />
    <child link="camera_infra1_frame" />
  </joint>
  <link name="camera_infra1_frame" />
  <joint name="camera_infra1_optical_joint" type="fixed">
    <origin rpy="-1.5707963267948966 0 -1.5707963267948966" xyz="0 0 0" />
    <parent link="camera_infra1_frame" />
    <child link="camera_infra1_optical_frame" />
  </joint>
  <link name="camera_infra1_optical_frame" />
  
  <joint name="camera_infra2_joint" type="fixed">
    <origin rpy="0 0 0" xyz="0 -0.05 0" />
    <parent link="camera_link" />
    <child link="camera_infra2_frame" />
  </joint>
  <link name="camera_infra2_frame" />
  <joint name="camera_infra2_optical_joint" type="fixed">
    <origin rpy="-1.5707963267948966 0 -1.5707963267948966" xyz="0 0 0" />
    <parent link="camera_infra2_frame" />
    <child link="camera_infra2_optical_frame" />
  </joint>
  <link name="camera_infra2_optical_frame" />
  
  <joint name="camera_color_joint" type="fixed">
    <origin rpy="0 0 0" xyz="0 0.015 0" />
    <parent link="camera_link" />
    <child link="camera_color_frame" />
  </joint>
  <link name="camera_color_frame" />
  <joint name="camera_color_optical_joint" type="fixed">
    <origin rpy="-1.5707963267948966 0 -1.5707963267948966" xyz="0 0 0" />
    <parent link="camera_color_frame" />
    <child link="camera_color_optical_frame" />
  </joint>
  <link name="camera_color_optical_frame" />
  <link name="camera_accel_frame" />
  <link name="camera_accel_optical_frame" />
  <link name="camera_gyro_frame" />
  <link name="camera_gyro_optical_frame" />
  <joint name="camera_accel_joint" type="fixed">
    <origin rpy="0 0 0" xyz="-0.01174 -0.00552 0.0051" />
    <parent link="camera_link" />
    <child link="camera_accel_frame" />
  </joint>
  <joint name="camera_accel_optical_joint" type="fixed">
    <origin rpy="-1.5707963267948966 0 -1.5707963267948966" xyz="0 0 0" />
    <parent link="camera_accel_frame" />
    <child link="camera_accel_optical_frame" />
  </joint>
  <joint name="camera_gyro_joint" type="fixed">
    <origin rpy="0 0 0" xyz="-0.01174 -0.00552 0.0051" />
    <parent link="camera_link" />
    <child link="camera_gyro_frame" />
  </joint>
  <joint name="camera_gyro_optical_joint" type="fixed">
    <origin rpy="-1.5707963267948966 0 -1.5707963267948966" xyz="0 0 0" />
    <parent link="camera_gyro_frame" />
    <child link="camera_gyro_optical_frame" />
  </joint>
  <link name="left_arm_flange">
    <visual>
      <origin rpy="0 0 0" xyz="0 0 0" />
      <geometry>
        <box size="0.001 0.001 0.001" />
      </geometry>
    </visual>
    <inertial>
      <origin rpy="0 0 0" xyz="0.0 0.0 0.0" />
      <mass value="0.001" />
      <inertia ixx="0.0000001" ixy="0.0" ixz="0.0" iyy="0.0000001" iyz="0.0" izz="0.0000001" />
    </inertial>
    <collision>
      <origin rpy="0 0 0" xyz="0 0 0" />
      <geometry>
        <box size="0.001 0.001 0.001" />
      </geometry>
    </collision>
  </link>
  <joint name="left_arm_flange_fix_joint" type="fixed">
    <parent link="tbase" />
    <child link="left_arm_flange" />
    <limit effort="2000" lower="0" upper="0" velocity="0" />
    <origin rpy="2.3562 0.0 -3.141592653589793" xyz="0.0 0.088 0.552" />
  </joint>
  <link name="right_arm_flange">
    <visual>
      <origin rpy="0 0 0" xyz="0 0 0" />
      <geometry>
        <box size="0.001 0.001 0.001" />
      </geometry>
    </visual>
    <inertial>
      <origin rpy="0 0 0" xyz="0.0 0.0 0.0" />
      <mass value="0.001" />
      <inertia ixx="0.0000001" ixy="0.0" ixz="0.0" iyy="0.0000001" iyz="0.0" izz="0.0000001" />
    </inertial>
    <collision>
      <origin rpy="0 0 0" xyz="0 0 0" />
      <geometry>
        <box size="0.001 0.001 0.001" />
      </geometry>
    </collision>
  </link>
  <joint name="right_arm_flange_fix_joint" type="fixed">
    <parent link="tbase" />
    <child link="right_arm_flange" />
    <limit effort="2000" lower="0" upper="0" velocity="0" />
    <origin rpy="-2.3565 0.0 3.141592653589793" xyz="0.0 -0.088 0.552" />
  </joint>
  <joint name="arm_left_joint_base" type="fixed">
    <parent link="left_arm_flange" />
    <child link="arm_left_base" />
    <limit effort="2000" lower="0" upper="0" velocity="0" />
    <origin rpy="0 0 0" xyz="0 0 -0.005" />
  </joint>
  <link name="arm_left_base">
    <visual>
      <geometry>
        <mesh filename="file://../../../dynaarm_description/meshes/baracuda12/base_mesh.dae" scale="1.0 1.0 1.0" />
      </geometry>
      <material name="carbon_fiber">
        <color rgba="0.792156862745098 0.819607843137255 0.933333333333333 1" />
      </material>
    </visual>
    <collision>
      <geometry>
        <cylinder length="0.1" radius="0.05" />
      </geometry>
      <origin rpy="0 0 0" xyz="0 0 0" />
    </collision>
    <inertial>
      <mass value="2.00205474" />
      <origin rpy="0 0 0" xyz="0.00347077 0.00328869 -0.0488212" />
      <inertia ixx="0.00403342" ixy="0.00040828" ixz="-0.00018775" iyy="0.00417534" iyz="-0.0001821" izz="0.00460211" />
    </inertial>
  </link>
  <link name="arm_left_shoulder">
    <visual>
      <geometry>
        <mesh filename="file://../../../dynaarm_description/meshes/baracuda12/shoulder_mesh.dae" scale="1.0 1.0 1.0" />
      </geometry>
    </visual>
    <inertial>
      <mass value="2.73096676" />
      <origin rpy="0 0 0" xyz="0.00001348 0.00013521 0.0430259" />
      <inertia ixx="0.01291668" ixy="0.0000044" ixz="-0.00000179" iyy="0.00874231" iyz="-0.00000203" izz="0.01243436" />
    </inertial>
    <collision>
      <geometry>
        <cylinder length="0.25" radius="0.06" />
      </geometry>
      <origin rpy="1.570796326795 0 0" xyz="0 0 0.05" />
    </collision>
  </link>
  <joint name="arm_left_shoulder_rotation" type="revolute">
    <parent link="arm_left_base" />
    <child link="arm_left_shoulder" />
    <axis xyz="0 0 1" />
    <limit command_effort="40" current="10" effort="40" gear_velocity="4" lower="-4.312388980385" upper="4.312388980385" velocity="4" />
    
    <origin rpy="0 0 0" xyz="0 0 0.1105" />
  </joint>
  <link name="arm_left_upperarm">
    <visual>
      <geometry>
        <mesh filename="file://../../../dynaarm_description/meshes/baracuda12/upperarm_mesh.dae" scale="1.0 1.0 1.0" />
      </geometry>
    </visual>
    <inertial>
      
      <mass value="2.12040464" />
      <origin rpy="0 0 0" xyz="0.20391301 -0.00000528 -0.00015224" />
      <inertia ixx="0.00155499" ixy="0.00000098" ixz="0.00004108" iyy="0.05067934" iyz="-0.00000143" izz="0.0507131" />
    </inertial>
    <collision>
      <geometry>
        <cylinder length="0.4" radius="0.05" />
      </geometry>
      <origin rpy="0 1.570796326795 0" xyz="0.15 0 0" />
    </collision>
  </link>
  <joint name="arm_left_shoulder_flexion" type="revolute">
    <parent link="arm_left_shoulder" />
    <child link="arm_left_upperarm" />
    <axis xyz="0 0 1" />
    <limit command_effort="40" current="10" effort="40" gear_velocity="4" lower="-1.720796326795" upper="1.720796326795" velocity="4" />
    
    <origin rpy="1.570796326795 -1.570796326795 0" xyz="0 0 0.047" />
  </joint>
  <link name="arm_left_elbow">
    <visual>
      <geometry>
        <mesh filename="file://../../../dynaarm_description/meshes/baracuda12/elbow_mesh.dae" scale="1.0 1.0 1.0" />
      </geometry>
    </visual>
    <inertial>
      <mass value="0.82320237" />
      <origin rpy="0 0 0" xyz="0.00383866 -0.07802638 -0.00026928" />
      <inertia ixx="0.00107419" ixy="0.00004166" ixz="-0.00000398" iyy="0.00087121" iyz="-0.0000119" izz="0.00113856" />
    </inertial>
    <collision>
      <geometry>
        <cylinder length="0.2" radius="0.065" />
      </geometry>
      <origin rpy="1.570796326795 0 0" xyz="-0.01 -0.05 0" />
    </collision>
  </link>
  <joint name="arm_left_elbow_flexion" type="revolute">
    <parent link="arm_left_upperarm" />
    <child link="arm_left_elbow" />
    <axis xyz="0 0 1" />
    <limit command_effort="40" current="10" effort="40" gear_velocity="4" lower="0.0" upper="3.0915926535900002" velocity="4" />
    
    <origin rpy="0 0 0" xyz="0.4127 0 0" />
  </joint>
  <link name="arm_left_elbow_camera_mount">
    <visual>
      <origin rpy="0 0 0" xyz="0 0 0" />
      <geometry>
        <box size="0.01 0.01 0.01" />
      </geometry>
    </visual>
    <inertial>
      <origin rpy="0 0 0" xyz="0.0 0.0 0.0" />
      <mass value="0.001" />
      <inertia ixx="1e-07" ixy="0.0" ixz="0.0" iyy="1e-07" iyz="0.0" izz="1e-07" />
    </inertial>
    <collision>
      <origin rpy="0 0 0" xyz="0 0 0" />
      <geometry>
        <box size="0.01 0.01 0.01" />
      </geometry>
    </collision>
  </link>
  <gazebo reference="arm_left_elbow_camera_mount">
    <kp>10000.0</kp>
    <kd>10.0</kd>
    <mu1>0.8</mu1>
    <mu2>0.8</mu2>
  </gazebo>
  <joint name="arm_left_elbow_camera" type="fixed">
    <parent link="arm_left_elbow" />
    <child link="arm_left_elbow_camera_mount" />
    <limit effort="2000" lower="0" upper="0" velocity="0" />
    <origin rpy="0.0 0.0 0.0" xyz="0.0345 -0.1235 0" />
  </joint>
  <link name="arm_left_forearm">
    <visual>
      <geometry>
        <mesh filename="file://../../../dynaarm_description/meshes/baracuda12/forearm_mesh.dae" scale="1.0 1.0 1.0" />
      </geometry>
    </visual>
    <inertial>
      <mass value="1.15674546" />
      <origin rpy="0 0 0" xyz="-0.00115165 0.00001056 0.30067314" />
      <inertia ixx="0.03129519" ixy="0.00000151" ixz="-0.00017171" iyy="0.03125954" iyz="0.00000159" izz="0.00090392" />
    </inertial>
    <collision>
      <geometry>
        <cylinder length="0.4" radius="0.04" />
      </geometry>
      <origin rpy="0 0 0" xyz="0 0 0.2" />
    </collision>
  </link>
  <joint name="arm_left_forearm_rotation" type="revolute">
    <parent link="arm_left_elbow" />
    <child link="arm_left_forearm" />
    <axis xyz="0 0 1" />
    <limit command_effort="40" current="10" effort="40" gear_velocity="4" lower="-4.7123889803850005" upper="4.7123889803850005" velocity="4" />
    
    <origin rpy="1.570796326795 1.570796326795 1.570796326795" xyz="0.0262 -0.0855 0" />
  </joint>
  <link name="arm_left_wrist_1">
    <visual>
      <geometry>
        <mesh filename="file://../../../dynaarm_description/meshes/baracuda12/wrist1_mesh.dae" scale="1.0 1.0 1.0" />
      </geometry>
    </visual>
    <inertial>
      
      <mass value="1.15007482" />
      <origin rpy="0 0 0" xyz="0.07972553 -0.00005038 0.02334747" />
      <inertia ixx="0.00065953" ixy="0.00000076" ixz="0.00011795" iyy="0.00088282" iyz="-0.00000079" izz="0.00078106" />
    </inertial>
    <collision>
      <geometry>
        <cylinder length="0.125" radius="0.05" />
      </geometry>
      <origin rpy="0 0 1.570796326795" xyz="0 0 0.025" />
    </collision>
  </link>
  <joint name="arm_left_wrist_flexion" type="revolute">
    <parent link="arm_left_forearm" />
    <child link="arm_left_wrist_1" />
    <axis xyz="0 0 1" />
    <limit command_effort="40" current="10" effort="40" gear_velocity="4" lower="-1.820796326795" upper="1.820796326795" velocity="4" />
    
    <origin rpy="0 -1.570796326795 0" xyz="0.0295 0 0.4207" />
  </joint>
  <link name="arm_left_wrist_1_camera_mount">
    <visual>
      <origin rpy="0 0 0" xyz="0 0 0" />
      <geometry>
        <box size="0.01 0.01 0.01" />
      </geometry>
    </visual>
    <inertial>
      <origin rpy="0 0 0" xyz="0.0 0.0 0.0" />
      <mass value="0.001" />
      <inertia ixx="1e-07" ixy="0.0" ixz="0.0" iyy="1e-07" iyz="0.0" izz="1e-07" />
    </inertial>
    <collision>
      <origin rpy="0 0 0" xyz="0 0 0" />
      <geometry>
        <box size="0.01 0.01 0.01" />
      </geometry>
    </collision>
  </link>
  <gazebo reference="arm_left_wrist_1_camera_mount">
    <kp>10000.0</kp>
    <kd>10.0</kd>
    <mu1>0.8</mu1>
    <mu2>0.8</mu2>
  </gazebo>
  <joint name="arm_left_wrist_flexion_camera" type="fixed">
    <parent link="arm_left_wrist_1" />
    <child link="arm_left_wrist_1_camera_mount" />
    <limit effort="2000" lower="0" upper="0" velocity="0" />
    <origin rpy="0.0 0.0 0.0" xyz="0.032 0 -0.017" />
  </joint>
  <link name="arm_left_wrist_2">
    <visual>
      <geometry>
        <mesh filename="file://../../../dynaarm_description/meshes/baracuda12/wrist2_mesh.dae" scale="1.0 1.0 1.0" />
      </geometry>
    </visual>
    <inertial>
      <mass value="0.0478406" />
      <origin rpy="0 0 0" xyz="0.00045711 0.00000557 0.00344945" />
      <inertia ixx="0.00001366" ixy="0" ixz="0.00000008" iyy="0.00001419" iyz="0" izz="0.00002702" />
    </inertial>
    <collision>
      <geometry>
        <cylinder length="0.09" radius="0.052" />
      </geometry>
      <origin rpy="0 0 0" xyz="0.005 0 -0.035" />
    </collision>
  </link>
  <joint name="arm_left_wrist_rotation" type="revolute">
    <parent link="arm_left_wrist_1" />
    <child link="arm_left_wrist_2" />
    <axis xyz="0 0 1" />
    <limit command_effort="40" current="10" effort="40" gear_velocity="4" lower="-4.7123889803850005" upper="4.7123889803850005" velocity="4" />
    
    <origin rpy="-1.570796326795 1.570796326795 -1.570796326795" xyz="0.117 0.0 0.0295" />
  </joint>
  <link name="arm_left_flange">
    <visual>
      <origin rpy="0 0 0" xyz="0 0 0" />
      <geometry>
        <box size="0.01 0.01 0.01" />
      </geometry>
    </visual>
    <inertial>
      <origin rpy="0 0 0" xyz="0.0 0.0 0.0" />
      <mass value="0.001" />
      <inertia ixx="1e-07" ixy="0.0" ixz="0.0" iyy="1e-07" iyz="0.0" izz="1e-07" />
    </inertial>
    <collision>
      <origin rpy="0 0 0" xyz="0 0 0" />
      <geometry>
        <box size="0.01 0.01 0.01" />
      </geometry>
    </collision>
  </link>
  <gazebo reference="arm_left_flange">
    <kp>10000.0</kp>
    <kd>10.0</kd>
    <mu1>0.8</mu1>
    <mu2>0.8</mu2>
  </gazebo>
  <joint name="arm_left_flange_fix_joint" type="fixed">
    <parent link="arm_left_wrist_2" />
    <child link="arm_left_flange" />
    <limit effort="2000" lower="0" upper="0" velocity="0" />
    <origin rpy="0.0 0.0 1.570796326795" xyz="0.0 0.0 0.009" />
  </joint>
  <ros2_control name="arm_left_DynaarmSystem" type="system">
    <hardware>
      <plugin>dynaarm_driver/DynaarmMockHardwareInterface</plugin>
      <param name="tf_prefix">arm_left_</param>
      <param name="start_in_freeze_mode">False</param>
      <param name="drive_parameter_folder">/ros2_ws/install/dynaarm_driver/share/dynaarm_driver/config/baracuda12</param>
      <param name="drive_parameter_folder_default">/ros2_ws/install/dynaarm_driver/share/dynaarm_driver/config/baracuda12</param>
      <param name="initial_positions">[0.05, 0.05, 0.10, 0.05, 0.05, 0.05]</param>
    </hardware>
    <joint name="arm_left_shoulder_rotation">
      <param name="address">1</param>
      <state_interface name="position">
        
        <param name="initial_value">0.05</param>
      </state_interface>
      <state_interface name="velocity" />
      <state_interface name="effort" />
      <state_interface name="motor_position" />
      <state_interface name="motor_velocity" />
      <state_interface name="motor_effort" />
      <state_interface name="motor_temperature_system" />
      <state_interface name="motor_temperature_coil_A" />
      <state_interface name="motor_temperature_coil_B" />
      <state_interface name="motor_temperature_coil_C" />
      <state_interface name="motor_bus_voltage" />
      <command_interface name="position" />
      <command_interface name="velocity" />
      <command_interface name="effort" />
      <command_interface name="p_gain" />
      <command_interface name="i_gain" />
      <command_interface name="d_gain" />
    </joint>
    <joint name="arm_left_shoulder_flexion">
      <param name="address">2</param>
      <state_interface name="position">
        
        <param name="initial_value">0.05</param>
      </state_interface>
      <state_interface name="velocity" />
      <state_interface name="effort" />
      <state_interface name="motor_position" />
      <state_interface name="motor_velocity" />
      <state_interface name="motor_effort" />
      <state_interface name="motor_temperature_system" />
      <state_interface name="motor_temperature_coil_A" />
      <state_interface name="motor_temperature_coil_B" />
      <state_interface name="motor_temperature_coil_C" />
      <state_interface name="motor_bus_voltage" />
      <command_interface name="position" />
      <command_interface name="velocity" />
      <command_interface name="effort" />
      <command_interface name="p_gain" />
      <command_interface name="i_gain" />
      <command_interface name="d_gain" />
    </joint>
    <joint name="arm_left_elbow_flexion">
      <param name="address">3</param>
      <state_interface name="position">
        
        <param name="initial_value">0.05</param>
      </state_interface>
      <state_interface name="velocity" />
      <state_interface name="effort" />
      <state_interface name="motor_position" />
      <state_interface name="motor_velocity" />
      <state_interface name="motor_effort" />
      <state_interface name="motor_temperature_system" />
      <state_interface name="motor_temperature_coil_A" />
      <state_interface name="motor_temperature_coil_B" />
      <state_interface name="motor_temperature_coil_C" />
      <state_interface name="motor_bus_voltage" />
      <command_interface name="position" />
      <command_interface name="velocity" />
      <command_interface name="effort" />
      <command_interface name="p_gain" />
      <command_interface name="i_gain" />
      <command_interface name="d_gain" />
    </joint>
    <joint name="arm_left_forearm_rotation">
      <param name="address">4</param>
      <state_interface name="position">
        
        <param name="initial_value">0.05</param>
      </state_interface>
      <state_interface name="velocity" />
      <state_interface name="effort" />
      <state_interface name="motor_position" />
      <state_interface name="motor_velocity" />
      <state_interface name="motor_effort" />
      <state_interface name="motor_temperature_system" />
      <state_interface name="motor_temperature_coil_A" />
      <state_interface name="motor_temperature_coil_B" />
      <state_interface name="motor_temperature_coil_C" />
      <state_interface name="motor_bus_voltage" />
      <command_interface name="position" />
      <command_interface name="velocity" />
      <command_interface name="effort" />
      <command_interface name="p_gain" />
      <command_interface name="i_gain" />
      <command_interface name="d_gain" />
    </joint>
    <joint name="arm_left_wrist_flexion">
      <param name="address">5</param>
      <state_interface name="position">
        
        <param name="initial_value">0.05</param>
      </state_interface>
      <state_interface name="velocity" />
      <state_interface name="effort" />
      <state_interface name="motor_position" />
      <state_interface name="motor_velocity" />
      <state_interface name="motor_effort" />
      <state_interface name="motor_temperature_system" />
      <state_interface name="motor_temperature_coil_A" />
      <state_interface name="motor_temperature_coil_B" />
      <state_interface name="motor_temperature_coil_C" />
      <state_interface name="motor_bus_voltage" />
      <command_interface name="position" />
      <command_interface name="velocity" />
      <command_interface name="effort" />
      <command_interface name="p_gain" />
      <command_interface name="i_gain" />
      <command_interface name="d_gain" />
    </joint>
    <joint name="arm_left_wrist_rotation">
      <param name="address">6</param>
      <state_interface name="position">
        
        <param name="initial_value">0.05</param>
      </state_interface>
      <state_interface name="velocity" />
      <state_interface name="effort" />
      <state_interface name="motor_position" />
      <state_interface name="motor_velocity" />
      <state_interface name="motor_effort" />
      <state_interface name="motor_temperature_system" />
      <state_interface name="motor_temperature_coil_A" />
      <state_interface name="motor_temperature_coil_B" />
      <state_interface name="motor_temperature_coil_C" />
      <state_interface name="motor_bus_voltage" />
      <command_interface name="position" />
      <command_interface name="velocity" />
      <command_interface name="effort" />
      <command_interface name="p_gain" />
      <command_interface name="i_gain" />
      <command_interface name="d_gain" />
    </joint>
    <gpio name="arm_left_DynaarmSystem">
      <command_interface name="freeze_mode" />
    </gpio>
  </ros2_control>
  <joint name="arm_right_joint_base" type="fixed">
    <parent link="right_arm_flange" />
    <child link="arm_right_base" />
    <limit effort="2000" lower="0" upper="0" velocity="0" />
    <origin rpy="0 0 0" xyz="0 0 -0.005" />
  </joint>
  <link name="arm_right_base">
    <visual>
      <geometry>
        <mesh filename="file://../../../dynaarm_description/meshes/baracuda12/base_mesh.dae" scale="1.0 1.0 1.0" />
      </geometry>
      <material name="carbon_fiber">
        <color rgba="0.792156862745098 0.819607843137255 0.933333333333333 1" />
      </material>
    </visual>
    <collision>
      <geometry>
        <cylinder length="0.1" radius="0.05" />
      </geometry>
      <origin rpy="0 0 0" xyz="0 0 0" />
    </collision>
    <inertial>
      <mass value="2.00205474" />
      <origin rpy="0 0 0" xyz="0.00347077 0.00328869 -0.0488212" />
      <inertia ixx="0.00403342" ixy="0.00040828" ixz="-0.00018775" iyy="0.00417534" iyz="-0.0001821" izz="0.00460211" />
    </inertial>
  </link>
  <link name="arm_right_shoulder">
    <visual>
      <geometry>
        <mesh filename="file://../../../dynaarm_description/meshes/baracuda12/shoulder_mesh.dae" scale="1.0 1.0 1.0" />
      </geometry>
    </visual>
    <inertial>
      <mass value="2.73096676" />
      <origin rpy="0 0 0" xyz="0.00001348 0.00013521 0.0430259" />
      <inertia ixx="0.01291668" ixy="0.0000044" ixz="-0.00000179" iyy="0.00874231" iyz="-0.00000203" izz="0.01243436" />
    </inertial>
    <collision>
      <geometry>
        <cylinder length="0.25" radius="0.06" />
      </geometry>
      <origin rpy="1.570796326795 0 0" xyz="0 0 0.05" />
    </collision>
  </link>
  <joint name="arm_right_shoulder_rotation" type="revolute">
    <parent link="arm_right_base" />
    <child link="arm_right_shoulder" />
    <axis xyz="0 0 1" />
    <limit command_effort="40" current="10" effort="40" gear_velocity="4" lower="-4.312388980385" upper="4.312388980385" velocity="4" />
    
    <origin rpy="0 0 0" xyz="0 0 0.1105" />
  </joint>
  <link name="arm_right_upperarm">
    <visual>
      <geometry>
        <mesh filename="file://../../../dynaarm_description/meshes/baracuda12/upperarm_mesh.dae" scale="1.0 1.0 1.0" />
      </geometry>
    </visual>
    <inertial>
      
      <mass value="2.12040464" />
      <origin rpy="0 0 0" xyz="0.20391301 -0.00000528 -0.00015224" />
      <inertia ixx="0.00155499" ixy="0.00000098" ixz="0.00004108" iyy="0.05067934" iyz="-0.00000143" izz="0.0507131" />
    </inertial>
    <collision>
      <geometry>
        <cylinder length="0.4" radius="0.05" />
      </geometry>
      <origin rpy="0 1.570796326795 0" xyz="0.15 0 0" />
    </collision>
  </link>
  <joint name="arm_right_shoulder_flexion" type="revolute">
    <parent link="arm_right_shoulder" />
    <child link="arm_right_upperarm" />
    <axis xyz="0 0 1" />
    <limit command_effort="40" current="10" effort="40" gear_velocity="4" lower="-1.720796326795" upper="1.720796326795" velocity="4" />
    
    <origin rpy="1.570796326795 -1.570796326795 0" xyz="0 0 0.047" />
  </joint>
  <link name="arm_right_elbow">
    <visual>
      <geometry>
        <mesh filename="file://../../../dynaarm_description/meshes/baracuda12/elbow_mesh.dae" scale="1.0 1.0 1.0" />
      </geometry>
    </visual>
    <inertial>
      <mass value="0.82320237" />
      <origin rpy="0 0 0" xyz="0.00383866 -0.07802638 -0.00026928" />
      <inertia ixx="0.00107419" ixy="0.00004166" ixz="-0.00000398" iyy="0.00087121" iyz="-0.0000119" izz="0.00113856" />
    </inertial>
    <collision>
      <geometry>
        <cylinder length="0.2" radius="0.065" />
      </geometry>
      <origin rpy="1.570796326795 0 0" xyz="-0.01 -0.05 0" />
    </collision>
  </link>
  <joint name="arm_right_elbow_flexion" type="revolute">
    <parent link="arm_right_upperarm" />
    <child link="arm_right_elbow" />
    <axis xyz="0 0 1" />
    <limit command_effort="40" current="10" effort="40" gear_velocity="4" lower="0.0" upper="3.0915926535900002" velocity="4" />
    
    <origin rpy="0 0 0" xyz="0.4127 0 0" />
  </joint>
  <link name="arm_right_elbow_camera_mount">
    <visual>
      <origin rpy="0 0 0" xyz="0 0 0" />
      <geometry>
        <box size="0.01 0.01 0.01" />
      </geometry>
    </visual>
    <inertial>
      <origin rpy="0 0 0" xyz="0.0 0.0 0.0" />
      <mass value="0.001" />
      <inertia ixx="1e-07" ixy="0.0" ixz="0.0" iyy="1e-07" iyz="0.0" izz="1e-07" />
    </inertial>
    <collision>
      <origin rpy="0 0 0" xyz="0 0 0" />
      <geometry>
        <box size="0.01 0.01 0.01" />
      </geometry>
    </collision>
  </link>
  <gazebo reference="arm_right_elbow_camera_mount">
    <kp>10000.0</kp>
    <kd>10.0</kd>
    <mu1>0.8</mu1>
    <mu2>0.8</mu2>
  </gazebo>
  <joint name="arm_right_elbow_camera" type="fixed">
    <parent link="arm_right_elbow" />
    <child link="arm_right_elbow_camera_mount" />
    <limit effort="2000" lower="0" upper="0" velocity="0" />
    <origin rpy="0.0 0.0 0.0" xyz="0.0345 -0.1235 0" />
  </joint>
  <link name="arm_right_forearm">
    <visual>
      <geometry>
        <mesh filename="file://../../../dynaarm_description/meshes/baracuda12/forearm_mesh.dae" scale="1.0 1.0 1.0" />
      </geometry>
    </visual>
    <inertial>
      <mass value="1.15674546" />
      <origin rpy="0 0 0" xyz="-0.00115165 0.00001056 0.30067314" />
      <inertia ixx="0.03129519" ixy="0.00000151" ixz="-0.00017171" iyy="0.03125954" iyz="0.00000159" izz="0.00090392" />
    </inertial>
    <collision>
      <geometry>
        <cylinder length="0.4" radius="0.04" />
      </geometry>
      <origin rpy="0 0 0" xyz="0 0 0.2" />
    </collision>
  </link>
  <joint name="arm_right_forearm_rotation" type="revolute">
    <parent link="arm_right_elbow" />
    <child link="arm_right_forearm" />
    <axis xyz="0 0 1" />
    <limit command_effort="40" current="10" effort="40" gear_velocity="4" lower="-4.7123889803850005" upper="4.7123889803850005" velocity="4" />
    
    <origin rpy="1.570796326795 1.570796326795 1.570796326795" xyz="0.0262 -0.0855 0" />
  </joint>
  <link name="arm_right_wrist_1">
    <visual>
      <geometry>
        <mesh filename="file://../../../dynaarm_description/meshes/baracuda12/wrist1_mesh.dae" scale="1.0 1.0 1.0" />
      </geometry>
    </visual>
    <inertial>
      
      <mass value="1.15007482" />
      <origin rpy="0 0 0" xyz="0.07972553 -0.00005038 0.02334747" />
      <inertia ixx="0.00065953" ixy="0.00000076" ixz="0.00011795" iyy="0.00088282" iyz="-0.00000079" izz="0.00078106" />
    </inertial>
    <collision>
      <geometry>
        <cylinder length="0.125" radius="0.05" />
      </geometry>
      <origin rpy="0 0 1.570796326795" xyz="0 0 0.025" />
    </collision>
  </link>
  <joint name="arm_right_wrist_flexion" type="revolute">
    <parent link="arm_right_forearm" />
    <child link="arm_right_wrist_1" />
    <axis xyz="0 0 1" />
    <limit command_effort="40" current="10" effort="40" gear_velocity="4" lower="-1.820796326795" upper="1.820796326795" velocity="4" />
    
    <origin rpy="0 -1.570796326795 0" xyz="0.0295 0 0.4207" />
  </joint>
  <link name="arm_right_wrist_1_camera_mount">
    <visual>
      <origin rpy="0 0 0" xyz="0 0 0" />
      <geometry>
        <box size="0.01 0.01 0.01" />
      </geometry>
    </visual>
    <inertial>
      <origin rpy="0 0 0" xyz="0.0 0.0 0.0" />
      <mass value="0.001" />
      <inertia ixx="1e-07" ixy="0.0" ixz="0.0" iyy="1e-07" iyz="0.0" izz="1e-07" />
    </inertial>
    <collision>
      <origin rpy="0 0 0" xyz="0 0 0" />
      <geometry>
        <box size="0.01 0.01 0.01" />
      </geometry>
    </collision>
  </link>
  <gazebo reference="arm_right_wrist_1_camera_mount">
    <kp>10000.0</kp>
    <kd>10.0</kd>
    <mu1>0.8</mu1>
    <mu2>0.8</mu2>
  </gazebo>
  <joint name="arm_right_wrist_flexion_camera" type="fixed">
    <parent link="arm_right_wrist_1" />
    <child link="arm_right_wrist_1_camera_mount" />
    <limit effort="2000" lower="0" upper="0" velocity="0" />
    <origin rpy="0.0 0.0 0.0" xyz="0.032 0 -0.017" />
  </joint>
  <link name="arm_right_wrist_2">
    <visual>
      <geometry>
        <mesh filename="file://../../../dynaarm_description/meshes/baracuda12/wrist2_mesh.dae" scale="1.0 1.0 1.0" />
      </geometry>
    </visual>
    <inertial>
      <mass value="0.0478406" />
      <origin rpy="0 0 0" xyz="0.00045711 0.00000557 0.00344945" />
      <inertia ixx="0.00001366" ixy="0" ixz="0.00000008" iyy="0.00001419" iyz="0" izz="0.00002702" />
    </inertial>
    <collision>
      <geometry>
        <cylinder length="0.09" radius="0.052" />
      </geometry>
      <origin rpy="0 0 0" xyz="0.005 0 -0.035" />
    </collision>
  </link>
  <joint name="arm_right_wrist_rotation" type="revolute">
    <parent link="arm_right_wrist_1" />
    <child link="arm_right_wrist_2" />
    <axis xyz="0 0 1" />
    <limit command_effort="40" current="10" effort="40" gear_velocity="4" lower="-4.7123889803850005" upper="4.7123889803850005" velocity="4" />
    
    <origin rpy="-1.570796326795 1.570796326795 -1.570796326795" xyz="0.117 0.0 0.0295" />
  </joint>
  <link name="arm_right_flange">
    <visual>
      <origin rpy="0 0 0" xyz="0 0 0" />
      <geometry>
        <box size="0.01 0.01 0.01" />
      </geometry>
    </visual>
    <inertial>
      <origin rpy="0 0 0" xyz="0.0 0.0 0.0" />
      <mass value="0.001" />
      <inertia ixx="1e-07" ixy="0.0" ixz="0.0" iyy="1e-07" iyz="0.0" izz="1e-07" />
    </inertial>
    <collision>
      <origin rpy="0 0 0" xyz="0 0 0" />
      <geometry>
        <box size="0.01 0.01 0.01" />
      </geometry>
    </collision>
  </link>
  <gazebo reference="arm_right_flange">
    <kp>10000.0</kp>
    <kd>10.0</kd>
    <mu1>0.8</mu1>
    <mu2>0.8</mu2>
  </gazebo>
  <joint name="arm_right_flange_fix_joint" type="fixed">
    <parent link="arm_right_wrist_2" />
    <child link="arm_right_flange" />
    <limit effort="2000" lower="0" upper="0" velocity="0" />
    <origin rpy="0.0 0.0 1.570796326795" xyz="0.0 0.0 0.009" />
  </joint>
  <ros2_control name="arm_right_DynaarmSystem" type="system">
    <hardware>
      <plugin>dynaarm_driver/DynaarmMockHardwareInterface</plugin>
      <param name="tf_prefix">arm_right_</param>
      <param name="start_in_freeze_mode">False</param>
      <param name="drive_parameter_folder">/ros2_ws/install/dynaarm_driver/share/dynaarm_driver/config/baracuda12</param>
      <param name="drive_parameter_folder_default">/ros2_ws/install/dynaarm_driver/share/dynaarm_driver/config/baracuda12</param>
      <param name="initial_positions">[0.05, 0.05, 0.10, 0.05, 0.05, 0.05]</param>
    </hardware>
    <joint name="arm_right_shoulder_rotation">
      <param name="address">1</param>
      <state_interface name="position">
        
        <param name="initial_value">0.05</param>
      </state_interface>
      <state_interface name="velocity" />
      <state_interface name="effort" />
      <state_interface name="motor_position" />
      <state_interface name="motor_velocity" />
      <state_interface name="motor_effort" />
      <state_interface name="motor_temperature_system" />
      <state_interface name="motor_temperature_coil_A" />
      <state_interface name="motor_temperature_coil_B" />
      <state_interface name="motor_temperature_coil_C" />
      <state_interface name="motor_bus_voltage" />
      <command_interface name="position" />
      <command_interface name="velocity" />
      <command_interface name="effort" />
      <command_interface name="p_gain" />
      <command_interface name="i_gain" />
      <command_interface name="d_gain" />
    </joint>
    <joint name="arm_right_shoulder_flexion">
      <param name="address">2</param>
      <state_interface name="position">
        
        <param name="initial_value">0.05</param>
      </state_interface>
      <state_interface name="velocity" />
      <state_interface name="effort" />
      <state_interface name="motor_position" />
      <state_interface name="motor_velocity" />
      <state_interface name="motor_effort" />
      <state_interface name="motor_temperature_system" />
      <state_interface name="motor_temperature_coil_A" />
      <state_interface name="motor_temperature_coil_B" />
      <state_interface name="motor_temperature_coil_C" />
      <state_interface name="motor_bus_voltage" />
      <command_interface name="position" />
      <command_interface name="velocity" />
      <command_interface name="effort" />
      <command_interface name="p_gain" />
      <command_interface name="i_gain" />
      <command_interface name="d_gain" />
    </joint>
    <joint name="arm_right_elbow_flexion">
      <param name="address">3</param>
      <state_interface name="position">
        
        <param name="initial_value">0.05</param>
      </state_interface>
      <state_interface name="velocity" />
      <state_interface name="effort" />
      <state_interface name="motor_position" />
      <state_interface name="motor_velocity" />
      <state_interface name="motor_effort" />
      <state_interface name="motor_temperature_system" />
      <state_interface name="motor_temperature_coil_A" />
      <state_interface name="motor_temperature_coil_B" />
      <state_interface name="motor_temperature_coil_C" />
      <state_interface name="motor_bus_voltage" />
      <command_interface name="position" />
      <command_interface name="velocity" />
      <command_interface name="effort" />
      <command_interface name="p_gain" />
      <command_interface name="i_gain" />
      <command_interface name="d_gain" />
    </joint>
    <joint name="arm_right_forearm_rotation">
      <param name="address">4</param>
      <state_interface name="position">
        
        <param name="initial_value">0.05</param>
      </state_interface>
      <state_interface name="velocity" />
      <state_interface name="effort" />
      <state_interface name="motor_position" />
      <state_interface name="motor_velocity" />
      <state_interface name="motor_effort" />
      <state_interface name="motor_temperature_system" />
      <state_interface name="motor_temperature_coil_A" />
      <state_interface name="motor_temperature_coil_B" />
      <state_interface name="motor_temperature_coil_C" />
      <state_interface name="motor_bus_voltage" />
      <command_interface name="position" />
      <command_interface name="velocity" />
      <command_interface name="effort" />
      <command_interface name="p_gain" />
      <command_interface name="i_gain" />
      <command_interface name="d_gain" />
    </joint>
    <joint name="arm_right_wrist_flexion">
      <param name="address">5</param>
      <state_interface name="position">
        
        <param name="initial_value">0.05</param>
      </state_interface>
      <state_interface name="velocity" />
      <state_interface name="effort" />
      <state_interface name="motor_position" />
      <state_interface name="motor_velocity" />
      <state_interface name="motor_effort" />
      <state_interface name="motor_temperature_system" />
      <state_interface name="motor_temperature_coil_A" />
      <state_interface name="motor_temperature_coil_B" />
      <state_interface name="motor_temperature_coil_C" />
      <state_interface name="motor_bus_voltage" />
      <command_interface name="position" />
      <command_interface name="velocity" />
      <command_interface name="effort" />
      <command_interface name="p_gain" />
      <command_interface name="i_gain" />
      <command_interface name="d_gain" />
    </joint>
    <joint name="arm_right_wrist_rotation">
      <param name="address">6</param>
      <state_interface name="position">
        
        <param name="initial_value">0.05</param>
      </state_interface>
      <state_interface name="velocity" />
      <state_interface name="effort" />
      <state_interface name="motor_position" />
      <state_interface name="motor_velocity" />
      <state_interface name="motor_effort" />
      <state_interface name="motor_temperature_system" />
      <state_interface name="motor_temperature_coil_A" />
      <state_interface name="motor_temperature_coil_B" />
      <state_interface name="motor_temperature_coil_C" />
      <state_interface name="motor_bus_voltage" />
      <command_interface name="position" />
      <command_interface name="velocity" />
      <command_interface name="effort" />
      <command_interface name="p_gain" />
      <command_interface name="i_gain" />
      <command_interface name="d_gain" />
    </joint>
    <gpio name="arm_right_DynaarmSystem">
      <command_interface name="freeze_mode" />
    </gpio>
  </ros2_control>
  <gazebo>
    <plugin filename="libgz_ros2_control-system.so" name="gz_ros2_control::GazeboSimROS2ControlPlugin">
      <parameters>/ros2_ws/install/duatic_control/share/duatic_control/config/controller_manager.yaml</parameters>
      <ros>
        <namespace>empty_namespace</namespace>
        <remapping>/robot_description:=robot_description</remapping>
        <remapping>/tf:=tf</remapping>
        <remapping>/tf_static:=tf_static</remapping>
        <remapping>/diagnostics:=diagnostics</remapping>
        <remapping>mecanum_drive_controller/reference:=cmd_vel</remapping>
      </ros>
    </plugin>
  </gazebo>
</robot>